Workbook

Sheet Instrucciones
A1: Formulario de extracción — Danny Valdiviezo
A2: 2026-08-11 · los 124 estudios extraíbles
A4: Empiece por la hoja Ejemplo. Son dos estudios ya resueltos.
A6: Lo que no debe hacer
A7: No abra el formulario del otro revisor ni el archivo de extracción del proyecto.
A8: Hay 42 estudios que ya se extrajeron y aun así salen en blanco aquí, a propósito:
A9: la comparación posterior solo mide algo si usted no vio lo que puso el otro.
A11: Las columnas
A12: Grises (A a G): identifican el estudio. No se tocan. La primera, Nº, es la clave
A13: con la que se cruzan las dos extracciones; si la cambia, se rompe el cruce.
A14: Amarillas: son suyas. Pase el ratón por cada encabezado y sale una nota
A15: explicando qué va en esa columna.
... A32: Guarde el archivo sin cambiarle el nombre y devuélvalo a quien coordina.

Sheet Extraccion
A1: Nº | B1: Pos. | C1: Título del artículo | D1: Revista | E1: Año | F1: Tipo | G1: Cómo encontrarlo | H1: Abrir artículo | I1: Id del estudio (Autor+Año) | J1: Brazo | K1: ¿Solo P. aeruginosa o mixto? | L1: Clase de resistencia | M1: ¿De dónde sale esa clase? | N1: ¿Cumple criterio DTR? | O1: Vía de administración | P1: ¿Fago solo o con antibiótico? | Q1: Diseño del estudio | R1: Estado de esta extracción | S1: Pacientes en este brazo | T1: Éxito clínico (nº pacientes) | U1: Eventos adversos (nº) | V1: Erradicación microbiológica (nº) | W1: Fallecidos (nº) | X1: Estancia hospitalaria (días) | Y1: Aparición de resistencia al fago (nº) | Z1: Año de publicación | AA1: ¿Cómo define el AUTOR el éxito clínico? | AB1: Nivel de la revista | AC1: País del estudio | AD1: ¿Dónde viste estos datos? | AE1: Si algo quedó incompleto, ¿por qué?
A2: EST-008 | B2: 12 | C2: Phage therapy with nebulized cocktail BX004-A for chronic Pseudomonas aeruginosa infections in cystic fibrosis: a randomized first-in-human trial. | D2: Nature Communications | E2: 2025 | F2: articulo | G2: 40593506 | H2: abrir | I2: Weiner2025 | J2: A | K2: solo Pseudomonas | L2: no clasificable | M2: verificado de forma independiente | N2: no | O2: inhalada/nebulizada | P2: fago + antibiotico | Q2: ECA | R2: PARCIAL | S2: 9 | T2: NA | U2: 0 | V2: 0 | W2: 0 | X2: NA | Y2: Na | Z2: 2025 | AA2: NA | AB2: alto | AC2: multicéntrico (internacional) | AD2: EN METODOS Y EN CLINICAL TRIAL | AE2: el antibiograma no permite clasificar la resistencia
A3: EST-021 | B3: 54 | C3: Efficacy and tolerability of a cocktail of bacteriophages to treat burn wounds infected by Pseudomonas aeruginosa (PhagoBurn): a randomised, controlled, double-blind phase 1/2 tria | D3: The Lancet. Infectious diseases | E3: 2019 | F3: articulo | G3: 30292481 | H3: abrir | I3: Jault2019 | J3: A | K3: mixto con subgrupo de Pseudomonas | L3: MDR | M3: declarado por el autor | N3: no | O3: topica/local | P3: fago + antibiotico | Q3: ECA | R3: PARCIAL | S3: 27 | T3: 17 | U3: 0 | V3: NA | W3: 0 | X3: NA | Y3: 0 | Z3: 2019 | AA3: como el tiempo mediano hasta lograr una reducción sostenida de la carga bacteriana | AB3: =IFERROR(IF(VLOOKUP(D3,Revistas!$A$21:$C$400,3,FALSE)=0,"",VLOOKUP(D3,Revistas!$A$21:$C$400,3,FALSE)),"") -> alto | AC3: multicéntrico (Europa) | AD3: FIGURA 1-4 | AE3: el antibiograma no permite clasificar la resistencia
A4: EST-035 | B4: 80 | C4: Safety and microbiological activity of phage therapy in persons with cystic fibrosis colonized with Pseudomonas aeruginosa: study protocol for a phase 1b/2, multicenter, randomized | D4: Trials | E4: 2022 | F4: articulo | G4: 36578069 | H4: abrir | I4: Tamma2022 | J4: A | K4: solo Pseudomonas | L4: MDR | M4: declarado por el autor | N4: no | O4: IV | P4: fago en monoterapia | Q4: ECA | R4: INCOMPLETA | S4: NA | T4: NA | U4: Na | V4: NA | W4: NA | X4: NA | Y4: NA | Z4: 2022 | AA4: El protocolo evalúa la actividad microbiológica mediante el cambio en los recuentos totales de colonias de P. aeruginosa en esputo ($\log_{10}$ CFU/mL) y el perfil global de beneficio-riesgo utilizando el ranking de deseabilidad de resultados | AB4: alto | AC4: Estados unidos | AD4: ABSTRACT FIGURA 1-3 | AE4: el artículo no reporta este desenlace
A5: EST-063 | B5: 181 | C5: Single-arm, open-labelled, safety and tolerability of intrabronchial and nebulised bacteriophage treatment in children with cystic fibrosis and Pseudomonas aeruginosa. | D5: BMJ open respiratory research | E5: 2023 | F5: articulo | G5: 10.1136/bmjresp-2022-001360 | H5: abrir | I5: Singh2023 | J5: A | K5: solo Pseudomonas | L5: no clasificable | M5: declarado por el autor | N5: no | O5: inhalada/nebulizada | P5: fago + antibiotico | Q5: ensayo no aleatorizado | R5: PARCIAL | S5: 10 | T5: NA | U5: Na | V5: NA | W5: NA | X5: 14 | Y5: Na | Z5: 2023 | AA5: evalúa la reducción de los títulos bacterianos de P. aeruginosa en esputo desde el inicio hasta el día 7. | AB5: alto | AC5: Australia | AD5: metodos y analisis | AE5: el artículo no reporta este desenlace
A6: EST-086 | B6: 361 | C6: Inhalation phage therapy as a new approach to preventing secondary bacterial pneumonia in patients with moderate to severe COVID-19: A double-blind clinical trial study | D6: Journal of Drug Delivery Science and Technology | E6: 2023 | F6: articulo | G6: 10.1016/j.jddst.2023.104486 | H6: abrir | I6: Samaee2023 | J6: A | K6: mixto con subgrupo de Pseudomonas | L6: MDR | M6: declarado por el autor | N6: no | O6: inhalada/nebulizada | P6: fago + antibiotico | Q6: ECA | R6: COMPLETA | S6: 30 | T6: 28 | U6: 0 | V6: 26 | W6: 1 | X6: 6 | Y6: Na | Z6: 2023 | AA6: e define como la recuperación dentro de los primeros 10 días de iniciado el tratamiento, caracterizada por un O2Sat ≥ 95%, y la ausencia de fiebre, disnea, tos, fatiga o recurrencias de infección pulmonar bacteriana secundaria | AB6: alto | AC6: Irán | AD6: resumen materiales y metodos | AE6: el artículo no reporta este desenlace
A7: EST-101 | B7: 498 | C7: The Efficacy of Inhaled Phage Cocktail to Prevent Ventilator-Associated Pneumonia in Children: A Double-Blind Clinical Trial | D7: Biomedicines | E7: 2025 | F7: articulo | G7: 10.3390/biomedicines13092103 | H7: abrir | I7: Navaeifar2025 | J7: A | K7: mixto con subgrupo de Pseudomonas | L7: MDR | M7: declarado por el autor | N7: no | O7: inhalada/nebulizada | P7: fago + antibiotico | Q7: ECA | R7: COMPLETA | S7: 30 | T7: 23 | U7: 0 | V7: NA | W7: 11 | X7: 51 | Y7: Na | Z7: 2025 | AA7: cura clinica | AB7: medio | AC7: Irán | AD7: ABSTRACT resumen y metodos | AE7: el artículo no reporta este desenlace
A8: EST-122 | B8: 753 | C8: Standardised treatment and monitoring protocol to assess safety and tolerability of bacteriophage therapy for adult and paediatric patients (STAMP study): protocol for an open-labe | D8: BMJ open | E8: 2022 | F8: articulo | G8: 10.1136/bmjopen-2022-065401 | H8: abrir | I8: Khatami2022 | J8: A | K8: mixto con subgrupo de Pseudomonas | L8: MDR | M8: declarado por el autor | N8: no | O8: inhalada/nebulizada | P8: fago + antibiotico | Q8: ensayo no aleatorizado | R8: INCOMPLETA | S8: NA | T8: NA | U8: Na | V8: NA | W8: NA | X8: NA | Y8: Na | Z8: 2022 | AA8: Como "cura", definida como la ausencia de evidencia de una infección en curso, lo que incluye falta de signos/síntomas clínicos, ausencia de anomalías radiológicas y de laboratorio, y sin evidencia microbiológica de infección | AB8: medio | AC8: Australia | AD8: Abstract", "Introduction" y "Methods and Analysis" | AE8: el artículo no reporta este desenlace
A9: EST-132 | B9: 869 | C9: Evaluation of the Potential Efficacy of Bacteriophage Therapy for the Management of Pressure Ulcers and Its Comparison to Conventional Therapy: A Randomized Controlled Trial | D9: Indian Journal of Critical Care Medicine | E9: 2026 | F9: articulo | G9: 10.5005/jp-journals-10071-25143 | H9: abrir | I9: Meena2026 | J9: A | K9: mixto con subgrupo de Pseudomonas | L9: MDR | M9: declarado por el autor | N9: no | O9: topica/local | P9: fago + antibiotico | Q9: ECA | R9: COMPLETA | S9: 38 | T9: 30 | U9: 0 | V9: NA | W9: 4 | X9: 28 | Y9: NA | Z9: 2026 | AA9: A través de la curación evaluada mediante la herramienta PUSH (Pressure Ulcer Scale for Healing), la reducción del tamaño de la úlcera, el tipo de tejido de cicatrización y la disminución en la cantidad de exudado | AB9: medio | AC9: India | AD9: bstract", "Patients and Methods", la Figura 1 de flujo de pacientes, la sección "Results | AE9: el artículo no reporta este desenlace
A10: EST-178 | B10: 3039 | C10: CLINICAL AND LABORATORY JUSTIFICATION FOR USE OF POLYVALENT BACTERIOPHAGE IN TECHNIQUE OF DELAYED PRESCRIBING OF ANTIBIOTICS IN PATIENTS WITH ARS. | D10: Wiadomosci lekarskie (Warsaw, Poland : 1960) | E10: 2021 | F10: articulo | G10: 10.36740/wlek202106129 | H10: abrir | I10: Popovych2021 | J10: A | K10: mixto con subgrupo de Pseudomonas | L10: no clasificable | M10: no clasificable | N10: no | O10: otra | P10: fago en monoterapia | Q10: ECA | R10: COMPLETA | S10: 80 | T10: NA | U10: 0 | V10: NA | W10: NA | X10: NA | Y10: Na | Z10: 2021 | AA10: A través de la evaluación de la reducción en la severidad de los síntomas mediante la escala MSS (Main Symptoms Severity score) en cada visita, la mejora en los niveles inmunológicos (IgA y sIgA) y la disminución en la frecuencia de prescripción de antibióticos | AB10: medio | AC10: otro | AD10: Abstract", "Materials and Methods", "Results", "Discussion" y la Tabla II del documento | AE10: el artículo no reporta este desenlace
A11: EST-181 | B11: 3367 | C11: Short-Term Outcomes of Phage-Antibiotic Combination Treatment in Adult Patients with Periprosthetic Hip Joint Infection. | D11: Viruses | E11: 2023 | F11: articulo | G11: 36851713 | H11: abrir | I11: Fedorov2023 | J11: A | K11: NA | L11: no clasificable | M11: declarado por el autor | N11: no | O11: otra | P11: fago + antibiotico | Q11: ensayo no aleatorizado | R11: COMPLETA | S11: 23 | T11: 21 | U11: 0 | V11: 22 | W11: 0 | X11: 31 | Y11: Na | Z11: 2023 | AA11: Como la ausencia de recaídas de la infección articular periprotésica (PJI) dentro del seguimiento de 12 meses tras la cirugía en una sola etapa. | AB11: =IFERROR(IF(VLOOKUP(D11,Revistas!$A$21:$C$400,3,FALSE)=0,"",VLOOKUP(D11,Revistas!$A$21:$C$400,3,FALSE)),"") -> medio | AC11: Rusia | AD11: metodos y analisis | AE11: el artículo no separa los datos de P. aeruginosa
A12: EST-029 | B12: 66 | C12: Randomized double-blind study on safety and tolerability of TP-102 phage cocktail in patients with infected and non-infected diabetic foot ulcers. | D12: Med (New York, N.Y.) | E12: 2025 | F12: articulo | G12: 39740667 | H12: abrir | I12: NirPaz2025 | J12: A | K12: mixto con subgrupo de Pseudomonas | L12: no clasificable | M12: declarado por el autor | N12: no | O12: topica/local | P12: fago en monoterapia | Q12: ECA | R12: INCOMPLETA | S12: 19 | T12: NA | U12: Na | V12: NA | W12: NA | X12: NA | Y12: Na | Z12: 2025 | AA12: NA | AB12: =IFERROR(IF(VLOOKUP(D12,Revistas!$A$21:$C$400,3,FALSE)=0,"",VLOOKUP(D12,Revistas!$A$21:$C$400,3,FALSE)),"") -> alto | AC12: Israel | AD12: NA | AE12: texto completo no accesible
A13: EST-052 | B13: 219 | C13: CYstic Fibrosis bacterioPHage study at Yale (CYPHY) | D13: Journal of cystic fibrosis | E13: 2023 | F13: articulo | G13: NCT04684641 | H13: abrir | I13: Koff2022 | J13: A | K13: solo Pseudomonas | L13: por debajo del umbral MDR | M13: declarado por el autor | N13: no | O13: inhalada/nebulizada | P13: fago en monoterapia | Q13: otra | R13: COMPLETA | S13: 24 | T13: NA | U13: Na | V13: NA | W13: NA | X13: NA | Y13: Na | Z13: 2022 | AA13: Reducción significativa de la carga bacteriana ($\text{UFC/mL}$) de P. aeruginosa en esputo al día 14, cambios en la función pulmonar ($FEV_1$ y $FEV_1pp$), reducción de exacerbaciones pulmonares y mejoría en escalas de síntomas (CFQ-R, CFRSD, CRISS). | AB13: NA | AC13: Estados Unidos | AD13: METODOS Y RESULTADOS | AE13: el antibiograma no permite clasificar la resistencia
A14: EST-078 | B14: 288 | C14: Efficacy of Bacteriophage Therapy in the Treatment of Diabetic Foot Ulcers: a Pilot Study from South India | D14: International journal of diabetes in developing countries | E14: 2025 | F14: resumen de congreso | G14: cita: Int J Diabetes Dev Ctries 2025 | H14: abrir | I14: NA | J14: A | K14: NA | L14: no clasificable | M14: no clasificable | N14: NO | O14: NA | P14: NA | Q14: NA | R14: INCOMPLETA | S14: NA | T14: NA | U14: Na | V14: NA | W14: NA | X14: NA | Y14: Na | Z14: na | AA14: NA | AB14: NA | AC14: NA | AD14: NA | AE14: texto completo no accesible
A15: EST-092 | B15: 399 | C15: Phage therapy analysis of effectiveness in comorbid patients with wounds and surgical infections of various etiology based on the results of a comparative clinical study; [Анализ э | D15: Pirogov Russian Journal of Surgery | E15: 2025 | F15: articulo | G15: 40103254 | H15: abrir | I15: Paskhalova2025 | J15: A | K15: NA | L15: no clasificable | M15: no clasificable | N15: NO | O15: NA | P15: NA | Q15: NA | R15: INCOMPLETA | S15: NA | T15: NA | U15: Na | V15: NA | W15: NA | X15: NA | Y15: Na | Z15: 2025 | AA15: NA | AB15: NA | AC15: Rusia | AD15: NA | AE15: texto completo no accesible
A16: EST-103 | B16: 506 | C16: Phage therapy of purulent wounds: comparative clinical cytomorphological and microbiological analysis of effectiveness; [Фаготерапиягнойныхран:сравнительныйклинико-цитоморфологичес | D16: Pirogov Russian Journal of Surgery | E16: 2026 | F16: articulo | G16: 41885494 | H16: abrir | I16: Paskhalova2026 | J16: A | K16: NA | L16: no clasificable | M16: no clasificable | N16: NO | O16: NA | P16: NA | Q16: NA | R16: INCOMPLETA | S16: NA | T16: NA | U16: Na | V16: NA | W16: NA | X16: NA | Y16: Na | Z16: 2026 | AA16: NA | AB16: NA | AC16: Rusia | AD16: NA | AE16: texto completo no accesible
A17: EST-118 | B17: 720 | C17: Intravesical bacteriophages for treating urinary tract infections in patients undergoing transurethral resection of the prostate: a randomised, placebo-controlled, double-blind cli | D17: The Lancet. Infectious diseases | E17: 2021 | F17: articulo | G17: 32949500 | H17: abrir | I17: Leitner2017 | J17: A | K17: mixto con subgrupo de Pseudomonas | L17: no clasificable | M17: declarado por el autor | N17: no | O17: intravesical | P17: fago en monoterapia | Q17: ECA | R17: PARCIAL | S17: 27 | T17: NA | U17: Na | V17: NA | W17: NA | X17: NA | Y17: Na | Z17: 2017 | AA17: omo el éxito del tratamiento intravesical, definido por la normalización del urocultivo (ausencia de evidencia de bacterias, es decir, < 10^4 unidades formadoras de colonias/mL) después de 7 días de tratamiento | AB17: =IFERROR(IF(VLOOKUP(D17,Revistas!$A$21:$C$400,3,FALSE)=0,"",VLOOKUP(D17,Revistas!$A$21:$C$400,3,FALSE)),"") -> alto | AC17: Estados unidos | AD17: DISEÑO Y METODOS | AE17: el antibiograma no permite clasificar la resistencia
A18: EST-126 | B18: 787 | C18: Application of bacteriophage therapy in the treatment of children with acute tonsillitis | D18: International Journal of Pediatrics and Adolescent Medicine | E18: 2024 | F18: articulo | G18: 10.4103/ijpam.ijpam_1_24 | H18: abrir | I18: Turdieva2024 | J18: A | K18: NA | L18: no clasificable | M18: declarado por el autor | N18: no | O18: inhalada/nebulizada | P18: fago + antibiotico | Q18: ECA | R18: COMPLETA | S18: 105 | T18: NA | U18: Na | V18: NA | W18: 0 | X18: 0 | Y18: Na | Z18: 2024 | AA18: Mediante criterios subjetivos (escala WADN de bienestar de 5 puntos evaluando sueño, apetito, estado de ánimo, dolor de cabeza, deglución, dolor de garganta y sequedad) y objetivos (reducción de signos de intoxicación, hiperemia e inflamación amigdalar, tamaño de ganglios linfáticos cervicales, recuento leucocitario y depuración en cultivo bacteriológico). | AB18: alto | AC18: otro | AD18: METODOS Y RESULTADOS | AE18: el artículo no separa los datos de P. aeruginosa
A19: EST-157 | B19: 1639 | C19: A Randomized, Placebo-controlled, Double-blind Clinical Trial of Bacteriophage Cocktails in Chronic Wound Infections. | D19: The international journal of lower extremity wounds | E19: 2026 | F19: articulo | G19: 38233034 | H19: abrir | I19: Karn2024 | J19: A | K19: NA | L19: no clasificable | M19: no clasificable | N19: no | O19: otra | P19: NA | Q19: NA | R19: INCOMPLETA | S19: NA | T19: NA | U19: Na | V19: NA | W19: NA | X19: NA | Y19: Na | Z19: 2024 | AA19: NA | AB19: medio | AC19: NA | AD19: NA | AE19: texto completo no accesible
A20: EST-167 | B20: 2267 | C20: Biological Therapy on Infected Traumatic Wounds: A Case-Control Study. | D20: The international journal of lower extremity wounds | E20: 2024 | F20: articulo | G20: 10.1177/15347346211072779 | H20: abrir | I20: Bhartiya2022 | J20: A | K20: NA | L20: no clasificable | M20: no clasificable | N20: no | O20: NA | P20: NA | Q20: NA | R20: INCOMPLETA | S20: NA | T20: NA | U20: Na | V20: NA | W20: NA | X20: NA | Y20: Na | Z20: 2022 | AA20: NA | AB20: medio | AC20: NA | AD20: NA | AE20: texto completo no accesible
A21: EST-173 | B21: 2761 | C21: Use of bacteriophages in the treatment of infected wounds in patients who have allergy to antibiotics | D21: Surgical Chronicles | E21: 2016 | F21: articulo | G21: cita: Surgical Chronicles 2016 | H21: abrir | I21: NA | J21: A | K21: NA | L21: no clasificable | M21: no clasificable | N21: NO | O21: NA | P21: NA | Q21: NA | R21: INCOMPLETA | S21: NA | T21: NA | U21: Na | V21: NA | W21: NA | X21: NA | Y21: Na | Z21: na | AA21: NA | AB21: NA | AC21: NA | AD21: NA | AE21: texto completo no accesible
A22: EST-177 | B22: 3017 | C22: A randomized, double-blind, placebo- -controlled study to investigate the use of bacteriophages in patients with chronic rhinosinusitis with nasal polyps. | D22: Otolaryngologia polska = The Polish otolaryngology | E22: 2021 | F22: articulo | G22: 35175218 | H22: abrir | I22: Dobretsov 2021 | J22: A | K22: NA | L22: no clasificable | M22: no clasificable | N22: NO | O22: NA | P22: NA | Q22: NA | R22: INCOMPLETA | S22: NA | T22: NA | U22: Na | V22: NA | W22: NA | X22: NA | Y22: Na | Z22: 2021 | AA22: NA | AB22: NA | AC22: NA | AD22: NA | AE22: texto completo no accesible
A23: EST-188 | B23: 4064 | C23: Potential treatment method of recurrent urinary tract infection in postmenopausal kidney transplant recipients: the results of pilot study | D23: Nephrology dialysis transplantation | E23: 2020 | F23: resumen de congreso | G23: cita: Nephrol Dial Transplant 2020 (resumen de congreso) | H23: abrir | I23: NA | J23: A | K23: NA | L23: no clasificable | M23: no clasificable | N23: NO | O23: NA | P23: NA | Q23: NA | R23: INCOMPLETA | S23: NA | T23: NA | U23: Na | V23: NA | W23: NA | X23: NA | Y23: Na | Z23: na | AA23: NA | AB23: NA | AC23: NA | AD23: NA | AE23: texto completo no accesible
A24: EST-219 | B24: 11138 | C24: Bacteriophages in complex treatment of septic diseases of the hand; [Использование лекарственных препаратов бактериофагов в комплексном лечении гнойных заболеваний кисти] | D24: Pirogov Russian Journal of Surgery | E24: 2023 | F24: articulo | G24: 10.17116/hirurgia202309145 | H24: abrir | I24: NA | J24: A | K24: NA | L24: no clasificable | M24: no clasificable | N24: NO | O24: NA | P24: NA | Q24: NA | R24: INCOMPLETA | S24: NA | T24: NA | U24: Na | V24: NA | W24: NA | X24: NA | Y24: Na | Z24: na | AA24: NA | AB24: NA | AC24: NA | AD24: NA | AE24: texto completo no accesible
A25: EST-004 | B25: 4 | C25: Personalized inhaled bacteriophage therapy for treatment of multidrug-resistant Pseudomonas aeruginosa in cystic fibrosis. | D25: Nature medicine | E25: 2025 | F25: articulo | G25: 10.1038/s41591-025-03678-8 | H25: abrir | I25: Chan2025 | J25: A | K25: solo Pseudomonas | L25: MDR | M25: declarado por el autor | N25: si | O25: inhalada/nebulizada | P25: fago + antibiotico | Q25: cohorte prospectiva | R25: COMPLETA | S25: 7 | T25: 7 | U25: 0 | V25: 7 | W25: 0 | X25: Na | Y25: Na | Z25: 2025 | AA25: Reducción de la carga bacteriana de Pseudomonas aeruginosa en esputo y mejora clínica en la función pulmonar (ppFEV1), respaldadas por compensaciones evolutivas (trade-offs) que redujeron la resistencia a los antibióticos o la virulencia bacteriana. | AB25: =IFERROR(IF(VLOOKUP(D25,Revistas!$A$21:$C$400,3,FALSE)=0,"",VLOOKUP(D25,Revistas!$A$21:$C$400,3,FALSE)),"") -> alto | AC25: Estados unidos | AD25: Tabla 2 Terapia personalizada con fagos | AE25: Na
A26: EST-004 | B26: 4 | C26: Personalized inhaled bacteriophage therapy for treatment of multidrug-resistant Pseudomonas aeruginosa in cystic fibrosis. | D26: Nature medicine | E26: 2025 | F26: articulo | G26: 10.1038/s41591-025-03678-8 | H26: abrir | I26: Chan2025 | J26: B | K26: solo Pseudomonas | L26: PDR | M26: declarado por el autor | N26: si | O26: inhalada/nebulizada | P26: fago + antibiotico | Q26: cohorte prospectiva | R26: COMPLETA | S26: 2 | T26: 2 | U26: 0 | V26: 2 | W26: 0 | X26: Na | Y26: Na | Z26: 2025 | AA26: Reducción de la carga bacteriana de Pseudomonas aeruginosa en esputo y mejora clínica en la función pulmonar (ppFEV1), respaldadas por compensaciones evolutivas (trade-offs) que redujeron la resistencia a los antibióticos o la virulencia bacteriana. | AB26: =IFERROR(IF(VLOOKUP(D26,Revistas!$A$21:$C$400,3,FALSE)=0,"",VLOOKUP(D26,Revistas!$A$21:$C$400,3,FALSE)),"") -> alto | AC26: Estados unidos | AD26: Tabla 2 Terapia personalizada con fagos | AE26: Na
A27: EST-024 | B27: 47 | C27: Bacteriophage Therapy for Pan-Drug-Resistant Pseudomonas aeruginosa in Two Persons With Cystic Fibrosis. | D27: Journal of investigative medicine high impact case reports | E27: 2023 | F27: articulo | G27: 10.1177/23247096231188243 | H27: abrir | I27: Hahn2023 | J27: A | K27: solo Pseudomonas | L27: PDR | M27: declarado por el autor | N27: SI | O27: inhalada/nebulizada | P27: fago + antibiotico | Q27: caso clinico | R27: COMPLETA | S27: 2 | T27: 2 | U27: 1 | V27: 0 | W27: 1 | X27: 7 | Y27: Na | Z27: 2023 | AA27: Disminución de la densidad bacteriana en el esputo y mejoría clínica a corto plazo (energía, menor tos productiva y mejoría temporal de los requerimientos de oxígeno). | AB27: =IFERROR(IF(VLOOKUP(D27,Revistas!$A$21:$C$400,3,FALSE)=0,"",VLOOKUP(D27,Revistas!$A$21:$C$400,3,FALSE)),"") -> medio | AC27: Estados unidos | AD27: DISEÑO Y METODOS | AE27: NA
A28: EST-039 | B28: 97 | C28: Adaptive Phage Therapy for the Prevention of Recurrent Nosocomial Pneumonia: Novel Protocol Description and Case Series | D28: Antibiotics | E28: 2023 | F28: articulo | G28: 10.3390/antibiotics12121734 | H28: abrir | I28: Zurabov2023 | J28: A | K28: mixto con subgrupo de Pseudomonas | L28: MDR | M28: declarado por el autor | N28: si | O28: inhalada/nebulizada | P28: fago en monoterapia | Q28: serie de casos | R28: COMPLETA | S28: 3 | T28: 3 | U28: 0 | V28: 3 | W28: 0 | X28: 28 | Y28: 0 | Z28: 2023 | AA28: La eliminación de microorganismos multirresistentes del lavado broncoalveolar, dinámicas positivas en las tomografías computarizadas de pulmón, mejora en el puntaje CPIS (Clinical Pulmonary Infection Score) y reducción significativa de los marcadores inflamatorios como la proteína C reactiva (PCR) y la procalcitonina. | AB28: =IFERROR(IF(VLOOKUP(D28,Revistas!$A$21:$C$400,3,FALSE)=0,"",VLOOKUP(D28,Revistas!$A$21:$C$400,3,FALSE)),"") -> medio | AC28: Rusia | AD28: DISEÑO Y METODOS | AE28: NA
A29: EST-042 | B29: 110 | C29: Phage therapy of perinephric abscess in kidney transplantation recipients caused by drug-resistant Pseudomonas aeruginosa. | D29: mLife | E29: 2025 | F29: articulo | G29: 10.1002/mlf2.70042 | H29: abrir | I29: Liu2025 | J29: A | K29: solo Pseudomonas | L29: PDR | M29: declarado por el autor | N29: si | O29: otra | P29: fago + antibiotico | Q29: caso clinico | R29: COMPLETA | S29: 2 | T29: 2 | U29: 0 | V29: 1 | W29: 0 | X29: NA | Y29: NA | Z29: 2025 | AA29: Erradicación completa de la bacteria patógena (cultivos negativos en heridas y orina), resolución clínica de la infección, cierre completo del tracto sinusal o fístula, reducción significativa de las áreas hipoecoicas/inflamatorias en estudios de imagen y mantenimiento de un estado clínico estable con calidad de vida normal | AB29: =IFERROR(IF(VLOOKUP(D29,Revistas!$A$21:$C$400,3,FALSE)=0,"",VLOOKUP(D29,Revistas!$A$21:$C$400,3,FALSE)),"") -> medio | AC29: China | AD29: DISEÑO Y METODOS | AE29: NA
A30: EST-055 | B30: 138 | C30: Bacteriophage therapy in women with chronic recurrent cystitis caused by multidrug-resistant bacteria: A prospective, observational, comparative study | D30: Current Urology | E30: 2025 | F30: articulo | G30: 10.1097/cu9.0000000000000268 | H30: abrir | I30: Krakhotkin2025 | J30: A | K30: NA | L30: MDR | M30: declarado por el autor | N30: no | O30: oral | P30: fago en monoterapia | Q30: cohorte prospectiva | R30: INCOMPLETA | S30: 45 | T30: NA | U30: 0 | V30: NA | W30: 0 | X30: 0 | Y30: 0 | Z30: 2025 | AA30: Como la reducción y mejoría estadísticamente significativa en los niveles de dolor medidos por la escala VAS y en las puntuaciones de los dominios (típicos, diferenciales y de calidad de vida) del cuestionario ACSS tras 14 días de tratamiento. | AB30: medio | AC30: Rusia | AD30: DISEÑO Y METODOS | AE30: el artículo no reporta este desenlace
A31: EST-074 | B31: 259 | C31: Bacteriophage Therapy for Critical Infections Related to Cardiothoracic Surgery. | D31: Antibiotics (Basel, Switzerland) | E31: 2020 | F31: articulo | G31: 10.3390/antibiotics9050232 | H31: abrir | I31: Rubalskii2020 | J31: A | K31: mixto con subgrupo de Pseudomonas | L31: MDR | M31: declarado por el autor | N31: no | O31: otra | P31: fago + antibiotico | Q31: serie de casos | R31: INCOMPLETA | S31: 8 | T31: 7 | U31: 0 | V31: 7 | W31: 3 | X31: NA | Y31: 0 | Z31: 2020 | AA31: Como la ausencia de detección de las bacterias objetivo en los cultivos de control (sangre, hisopados, lavados bronquiales o drenajes) junto con la curación de heridas y ausencia de signos inflamatorios en imágenes de seguimiento por PET-CT. | AB31: alto | AC31: Alemania | AD31: DISEÑO Y METODOS | AE31: datos solo del estudio entero, no por brazo
A32: EST-075 | B32: 264 | C32: Phage therapy in antibiotic resistant pneumonia: Immunomodulation or redistribution? | D32: Medical Immunology (Russia) | E32: 2021 | F32: articulo | G32: 10.15789/1563-0625-pti-2012 | H32: abrir | I32: Bochkareva2021 | J32: A | K32: NA | L32: MDR | M32: declarado por el autor | N32: no | O32: NA | P32: fago + antibiotico | Q32: ECA | R32: INCOMPLETA | S32: 19 | T32: 19 | U32: NA | V32: 19 | W32: NA | X32: NA | Y32: NA | Z32: 2021 | AA32: Como la sanación de las vías respiratorias (airway sanitation) junto con la superación de la linfopenia y el aumento de la cantidad y actividad funcional de los linfocitos de sangre periférica | AB32: medio | AC32: Rusia | AD32: MATERILAES Y METODOS | AE32: datos solo del estudio entero, no por brazo
A33: EST-077 | B33: 278 | C33: Pseudomonas aeruginosa ventricular assist device infections: findings from ineffective phage therapies in five cases. | D33: Antimicrobial agents and chemotherapy | E33: 2024 | F33: articulo | G33: 10.1128/aac.01728-23 | H33: abrir | I33: Aslam2024 | J33: A | K33: solo Pseudomonas | L33: MDR | M33: declarado por el autor | N33: no | O33: IV | P33: fago + antibiotico | Q33: cohorte retrospectiva | R33: COMPLETA | S33: 4 | T33: 0 | U33: 3 | V33: 0 | W33: 2 | X33: NA | Y33: Na | Z33: 2024 | AA33: El autor no lista criterios estandarizados de éxito, pero enmarca el fracaso clínico por la presencia de bacteriemia intercurrente, la imposibilidad de curar la infección sin retirar el dispositivo de asistencia ventricular (LVAD) y la muerte por la infección subyacente | AB33: =IFERROR(IF(VLOOKUP(D33,Revistas!$A$21:$C$400,3,FALSE)=0,"",VLOOKUP(D33,Revistas!$A$21:$C$400,3,FALSE)),"") -> medio | AC33: multicéntrico (internacional) | AD33: resumen materiales y metodos | AE33: NA
A34: EST-080 | B34: 321 | C34: Bacteriophage Therapy as a Potential Management Option for Surgical Wound Infections | D34: PHAGE: Therapy, Applications, and Research | E34: 2020 | F34: articulo | G34: 10.1089/phage.2020.0010 | H34: abrir | I34: Nadareishvili 2020 | J34: A | K34: solo Pseudomonas | L34: MDR | M34: declarado por el autor | N34: no | O34: oral | P34: fago en monoterapia | Q34: cohorte retrospectiva | R34: COMPLETA | S34: 1 | T34: 1 | U34: 0 | V34: NA | W34: 0 | X34: NA | Y34: 0 | Z34: 2020 | AA34: Curación completa de la herida, cierre del tejido, regeneración con formación de tejido de granulación, desaparición del eritema de la piel y mejora del estado general. | AB34: alto | AC34: Estados unidos | AD34: INTRODUCCION CASE 4 Y RESULTADOS | AE34: el artículo no reporta este desenlace
A35: EST-091 | B35: 387 | C35: Analysis of Pro- and Anti-Inflammatory Gene Response Patterns in Patients Receiving Phage Therapy. | D35: International journal of molecular sciences | E35: 2025 | F35: articulo | G35: 10.3390/ijms27010172 | H35: abrir | I35: Kasprzak2026 | J35: A | K35: mixto con subgrupo de Pseudomonas | L35: no clasificable | M35: declarado por el autor | N35: no | O35: otra | P35: fago en monoterapia | Q35: otra | R35: COMPLETA | S35: 10 | T35: 4 | U35: 0 | V35: NA | W35: 0 | X35: 29 | Y35: 0 | Z35: 2026 | AA35: Escala clínica A–G de Międzybrodzki | AB35: alto | AC35: Polonia | AD35: Abstract, Sección 2.1 (Tabla 1) y Sección 4.1 (Materiales y Métodos) | AE35: el artículo no separa los datos de P. aeruginosa
A36: EST-108 | B36: 606 | C36: Personalized bacteriophage therapy outcomes for 100 consecutive cases: a multicentre, multinational, retrospective observational study. | D36: Nature microbiology | E36: 2024 | F36: articulo | G36: 10.1038/s41564-024-01705-x | H36: abrir | I36: Pirnay2024 | J36: A | K36: mixto con subgrupo de Pseudomonas | L36: por debajo del umbral MDR | M36: declarado por el autor | N36: no | O36: otra | P36: fago + antibiotico | Q36: cohorte retrospectiva | R36: COMPLETA | S36: 20 | T36: NA | U36: Na | V36: NA | W36: NA | X36: NA | Y36: 0 | Z36: 2024 | AA36: Evaluación del médico tratante (“clinical improvement”). No usaron criterios pre-especificados uniformes. | AB36: =IFERROR(IF(VLOOKUP(D36,Revistas!$A$21:$C$400,3,FALSE)=0,"",VLOOKUP(D36,Revistas!$A$21:$C$400,3,FALSE)),"") -> alto | AC36: multicéntrico (Europa) | AD36: Artículo principal + Supplementary Table 1 | AE36: el artículo no reporta este desenlace
A37: EST-108 | B37: 606 | C37: Personalized bacteriophage therapy outcomes for 100 consecutive cases: a multicentre, multinational, retrospective observational study. | D37: Nature microbiology | E37: 2024 | F37: articulo | G37: 10.1038/s41564-024-01705-x | H37: abrir | I37: Pirnay2024 | J37: B | K37: mixto con subgrupo de Pseudomonas | L37: MDR | M37: declarado por el autor | N37: no | O37: otra | P37: fago + antibiotico | Q37: cohorte retrospectiva | R37: COMPLETA | S37: 17 | T37: NA | U37: Na | V37: NA | W37: NA | X37: NA | Y37: 3 | Z37: 2024 | AA37: Evaluación del médico tratante (“clinical improvement”). No usaron criterios pre-especificados uniformes. | AB37: =IFERROR(IF(VLOOKUP(D37,Revistas!$A$21:$C$400,3,FALSE)=0,"",VLOOKUP(D37,Revistas!$A$21:$C$400,3,FALSE)),"") -> alto | AC37: multicéntrico (Europa) | AD37: Artículo principal + Supplementary Table 2 | AE37: el artículo no reporta este desenlace
A38: EST-108 | B38: 606 | C38: Personalized bacteriophage therapy outcomes for 100 consecutive cases: a multicentre, multinational, retrospective observational study. | D38: Nature microbiology | E38: 2024 | F38: articulo | G38: 10.1038/s41564-024-01705-x | H38: abrir | I38: Pirnay2024 | J38: C | K38: mixto con subgrupo de Pseudomonas | L38: XDR | M38: declarado por el autor | N38: no | O38: otra | P38: fago + antibiotico | Q38: cohorte retrospectiva | R38: COMPLETA | S38: 11 | T38: NA | U38: Na | V38: NA | W38: NA | X38: NA | Y38: 3 | Z38: 2024 | AA38: Evaluación del médico tratante (“clinical improvement”). No usaron criterios pre-especificados uniformes. | AB38: =IFERROR(IF(VLOOKUP(D38,Revistas!$A$21:$C$400,3,FALSE)=0,"",VLOOKUP(D38,Revistas!$A$21:$C$400,3,FALSE)),"") -> alto | AC38: multicéntrico (Europa) | AD38: Artículo principal + Supplementary Table 3 | AE38: el artículo no reporta este desenlace
A39: EST-108 | B39: 606 | C39: Personalized bacteriophage therapy outcomes for 100 consecutive cases: a multicentre, multinational, retrospective observational study. | D39: Nature microbiology | E39: 2024 | F39: articulo | G39: 10.1038/s41564-024-01705-x | H39: abrir | I39: Pirnay2024 | J39: D | K39: mixto con subgrupo de Pseudomonas | L39: PDR | M39: declarado por el autor | N39: no | O39: otra | P39: fago + antibiotico | Q39: cohorte retrospectiva | R39: COMPLETA | S39: 2 | T39: NA | U39: Na | V39: NA | W39: NA | X39: NA | Y39: 0 | Z39: 2024 | AA39: Evaluación del médico tratante (“clinical improvement”). No usaron criterios pre-especificados uniformes. | AB39: =IFERROR(IF(VLOOKUP(D39,Revistas!$A$21:$C$400,3,FALSE)=0,"",VLOOKUP(D39,Revistas!$A$21:$C$400,3,FALSE)),"") -> alto | AC39: multicéntrico (Europa) | AD39: Artículo principal + Supplementary Table 4 | AE39: el artículo no reporta este desenlace
A40: EST-116 | B40: 687 | C40: Processing Phage Therapy Requests in a Brussels Military Hospital: Lessons Identified. | D40: Viruses | E40: 2019 | F40: articulo | G40: 10.3390/v11030265 | H40: abrir | I40: Djebara2019 | J40: A | K40: mixto con subgrupo de Pseudomonas | L40: MDR | M40: declarado por el autor | N40: no | O40: otra | P40: fago + antibiotico | Q40: ensayo no aleatorizado | R40: COMPLETA | S40: 260 | T40: NA | U40: Na | V40: NA | W40: NA | X40: NA | Y40: Na | Z40: 2019 | AA40: NA | AB40: =IFERROR(IF(VLOOKUP(D40,Revistas!$A$21:$C$400,3,FALSE)=0,"",VLOOKUP(D40,Revistas!$A$21:$C$400,3,FALSE)),"") -> medio | AC40: Bélgica | AD40: MATERILAES Y METODOS | AE40: el artículo no separa los datos de P. aeruginosa
...

Sheet Revistas
A1: Nivel de cada revista — se decide UNA vez por revista, no por estudio
A3: Criterio de esta revisión (memo de estrategia, comprobación de falsación nº2):
A4: el nivel es un indicador grueso, solo sirve para comprobar que la revista no
A5: predice el resultado agrupado. No hace falta afinar: basta alto / medio / bajo.
A7: alto revista general o de infecciosas de primera línea (Nature Microbiology,
A8: Lancet Infect Dis, Clinical Infectious Diseases, Nature Communications…)
A9: medio revista especializada con revisión por pares (Viruses, Antibiotics,
A10: Antimicrob Agents Chemother, Frontiers…)
A11: bajo revista local, sin indexación reconocible o sin revisión por pares clara
A12: solo registro no es una revista: es una ficha de ensayo
A14: Si duda, búsquela en scimagojr.com: Q1 y Q2 -> alto o medio; Q3, Q4 o sin
A15: cuartil -> bajo. Anote la fuente en la última columna.
... A18: cambie sin motivo: cambiarlas descuadra los 42 estudios ya codificados.
A20: Revista | B20: Estudios | C20: Nivel | D20: Propuesta (confirmar) | E20: Fuente / nota
A21: Antibiotics | B21: 9 | C21: medio | E21: corpus del proyecto
A22: Viruses | B22: 9 | C22: medio | E22: corpus del proyecto
A23: Nature Communications | B23: 8 | C23: alto | E23: corpus del proyecto
A24: Frontiers in medicine | B24: 6 | C24: medio | E24: corpus del proyecto
A25: Pirogov Russian Journal of Surgery | B25: 4 | E25: buscar en scimagojr.com
A26: The international journal of lower extremity wounds | B26: 4 | D26: medio | E26: propuesta: confirmar
A27: International journal of antimicrobial agents | B27: 3 | D27: medio | E27: propuesta: confirmar
A28: Med (New York, N.Y.) | B28: 3 | C28: alto | E28: corpus del proyecto
A29: Open forum infectious diseases | B29: 3 | C29: medio | E29: corpus del proyecto
A30: The Lancet. Infectious diseases | B30: 3 | C30: alto | E30: corpus del proyecto
A31: Antimicrobial agents and chemotherapy | B31: 2 | C31: medio | E31: corpus del proyecto
A32: ASM case reports | B32: 2 | C32: medio | E32: corpus del proyecto
A33: Clinical infectious diseases : an official publication of the Infectious Diseases Society of America | B33: 2 | C33: alto | E33: corpus del proyecto
A34: Infektsionnye Bolezni | B34: 2 | E34: buscar en scimagojr.com
A35: International journal of infectious diseases : IJID : official publication of the International Society for Infectious Diseases | B35: 2 | C35: medio | E35: corpus del proyecto
A36: JAC-antimicrobial resistance | B36: 2 | D36: medio | E36: propuesta: confirmar
A37: Scientific reports | B37: 2 | C37: alto | E37: corpus del proyecto
A38: The Journal of heart and lung transplantation : the official publication of the International Society for Heart Transplantation | B38: 2 | D38: alto | E38: propuesta: confirmar
A39: American journal of respiratory and critical care medicine | B39: 1 | C39: alto | E39: corpus del proyecto
A40: American journal of transplantation : official journal of the American Society of Transplantation and the American Society of Transplant Surgeons | B40: 1 | C40: alto | E40: corpus del proyecto
A41: Annals of Vascular Surgery - Brief Reports and Innovations | B41: 1 | D41: medio | E41: propuesta: confirmar
A42: Biomedicines | B42: 1 | D42: medio | E42: propuesta: confirmar
A43: Bioscience trends | B43: 1 | C43: medio | E43: corpus del proyecto
A44: BMJ open | B44: 1 | D44: medio | E44: propuesta: confirmar
A45: BMJ open respiratory research | B45: 1 | D45: medio | E45: propuesta: confirmar
A46: Clinical Medicine Insights: Case Reports | B46: 1 | D46: bajo | E46: propuesta: confirmar
...

Sheet Listas
A1: País | B1: Nivel de revista | C1: Motivo si quedó incompleto
A2: Alemania | B2: alto | C2: NA
A3: Australia | B3: medio | C3: texto completo no accesible
A4: Bélgica | B4: bajo | C4: el artículo no separa los datos de P. aeruginosa
A5: Canadá | B5: solo registro | C5: el artículo no reporta este desenlace
A6: China | C6: solo resumen de congreso: datos limitados
A7: Corea del Sur | C7: datos solo del estudio entero, no por brazo
A8: Dinamarca | C8: el antibiograma no permite clasificar la resistencia
A9: Ecuador | C9: otro (explicar al lado)
A10: España
A11: Estados Unidos
A12: Francia
A13: Georgia
A14: India
A15: Irán
A16: Israel
A17: Italia
A18: Japón
A19: Letonia
A20: Países Bajos
A21: Polonia
... A29: otro

Sheet Diccionario
A1: Columna | B1: Qué se contesta | C1: Opciones
A2: Id del estudio (Autor+Año) | B2: Apellido del primer autor pegado al año: Tkhilaishvili2020. Sin espacios ni tildes.
A3: Brazo | B3: A si el estudio da un solo grupo de datos. Si separa desenlaces por clase de resistencia, usa A, B, C.
A4: ¿Solo P. aeruginosa o mixto? | B4: Solo Pseudomonas si todos los pacientes tenían P. aeruginosa. Mixto si había otras bacterias PERO el artículo permite separar los de Pseudomonas. | C4: solo Pseudomonas · mixto con subgrupo de Pseudomonas
A5: Clase de resistencia | B5: MDR, XDR o PDR según Magiorakos. Si el antibiograma no alcanza para clasificar, pon 'no clasificable'. | C5: MDR · XDR · PDR · por debajo del umbral MDR · no clasificable
A6: ¿De dónde sale esa clase? | B6: ¿Lo dice el autor y lo aceptaste, o lo verificaste tú con el antibiograma? Importa para el riesgo de sesgo. | C6: declarado por el autor · verificado de forma independiente · no clasificable
A7: ¿Cumple criterio DTR? | B7: Difficult-to-Treat Resistance (Kadri 2018, PMID 30052813). NO es MDR con otro nombre: pregunta si se agotaron los antibióticos de PRIMERA LÍNEA (carbapenémicos, otros betalactámicos, fluoroquinolonas). Los de RESERVA -- colistina, aminoglucósidos, tigeciclina -- y los posteriores a 2018 -- ceftazidima-avibactam, cefiderocol -- NO cuentan: son aquello a lo que el DTR obliga a recurrir. SÍ: el artículo documenta sensibilidad SOLO a agentes de reserva. NO: basta UN agente de primera línea sensible documentado. NO DERIVABLE: el resto. Ojo: esta revisión ya definió mal este campo una vez (exigía 'todos los betalactámicos', más estricto que Kadri) y fabricó no-derivabilidad. Si duda entre 'no' y 'no derivable', mire si hay UN solo agente de primera línea sensible. | C7: si · no · no derivable
A8: Vía de administración | B8: Por dónde se administró el fago. Si fueron varias vías, elige 'otra' y explica en el paréntesis. | C8: IV · inhalada/nebulizada · topica/local · oral · intravesical · intraarticular · otra · NA
A9: ¿Fago solo o con antibiótico? | B9: ¿El fago fue solo, o junto con antibióticos? | C9: fago en monoterapia · fago + antibiotico · fago + otro · NA
A10: Diseño del estudio | B10: Lo que el artículo ES, no lo que dice ser. Un 'estudio' de un paciente es un caso clínico. | C10: ECA · caso clinico · serie de casos · cohorte retrospectiva · cohorte prospectiva · ensayo no aleatorizado · otra
A11: Estado de esta extracción | B11: COMPLETA si sacaste todo lo que el artículo daba. PARCIAL o INCOMPLETA si te faltó algo, y explícalo en la última columna. | C11: COMPLETA · PARCIAL · INCOMPLETA
A12: Pacientes en este brazo | B12: Cuántos pacientes hay en ESTE brazo, no en todo el estudio.
A13: Éxito clínico (nº pacientes) | B13: Pacientes de este brazo que mejoraron según la definición del PROPIO autor. · un número = el artículo lo dice o permite contarlo · 0 = el artículo dice que ninguno mejoró · NA = no lo reporta ni permite deducirlo Si el autor no define el éxito pero dice «los tres pacientes se curaron», la cifra SÍ se extrae: pon 3, y escribe SIN DEFINICIÓN OPERATIVA en la columna de definición.
A14: Eventos adversos (nº) | B14: Cuántos pacientes tuvieron algún evento adverso. Cero notificados se escribe 0, no NA.
A15: Erradicación microbiológica (nº) | B15: Pacientes con CULTIVO DE CONTROL NEGATIVO para P. aeruginosa, del mismo sitio de infección, DESPUÉS de terminar la fagoterapia. Se toma el primer cultivo posterior al fin del tratamiento; anota el día en observaciones. Los tres valores NO son intercambiables: · un número = se hizo cultivo y salió negativo en esos pacientes · 0 = se hizo cultivo y SIGUIÓ POSITIVO en todos · NA = no se hizo, o no se reporta, cultivo de control FIBROSIS QUÍSTICA Y BRONQUIECTASIAS: un solo cultivo negativo NO cuenta como erradicación. En colonización crónica la carga fluctúa y un cultivo aislado no demuestra eliminación. Anota NA y explícalo, salvo que el artículo declare erradicación sostenida con cultivos seriados. Regla completa y por qué: quality_reports/decisions/2026-08-11_definicion-erradicacion-y-exito.md
A16: Fallecidos (nº) | B16: Cuántos fallecieron durante el seguimiento.
A17: Estancia hospitalaria (días) | B17: Días de hospitalización. Casi ningún caso clínico lo reporta: NA es lo normal aquí.
A18: Aparición de resistencia al fago (nº) | B18: En cuántos apareció resistencia al fago durante el tratamiento.
A19: Año de publicación | B19: Año del artículo.
A20: ¿Cómo define el AUTOR el éxito clínico? | B20: COPIA la definición del autor. No escribas la tuya. Si el artículo NO define qué considera éxito clínico, escribe exactamente: SIN DEFINICIÓN OPERATIVA y nada más. NO pegues una frase de la Discusión ni de las Conclusiones. Cómo distinguirlas: la definición es una CONDICIÓN («resolución de los signos inflamatorios a las 12 semanas»); el resultado es un DESENLACE («el paciente evolucionó favorablemente»). Solo la primera va aquí. Que la mayoría de los estudios no lo defina ES UN HALLAZGO del manuscrito. Si rellenas el hueco con una frase cualquiera, el hueco desaparece del registro y con él la prueba de que existía.
A21: Nivel de la revista | B21: Nombre de la revista, y si es de alto o medio impacto: 'alto (Nature Microbiology)'.
A22: País del estudio | B22: País y ciudad si consta: 'Alemania (Berlín)'.
A23: ¿Dónde viste estos datos? | B23: Página, tabla o figura de donde sacaste los números: 'p.3 Results, Tabla 2'. Obligatorio para cualquier cifra.
A24: Si algo quedó incompleto, ¿por qué? | B24: Qué faltó y por qué. NA si no faltó nada.

Sheet Ejemplo
A1: Dos ejemplos resueltos
A2: Salen de estudios que ya se extrajeron en este proyecto.
A4: EJEMPLO 1 — un solo brazo
A5: Tkhilaishvili 2020. Un paciente con infección de prótesis por P. aeruginosa XDR,
A6: tratado con fago más antibiótico por vía local. Curó.
A8: Columna | B8: Qué escribí | C8: Por qué
A9: Id del estudio (Autor+Año) | B9: Tkhilaishvili2020 | C9: apellido pegado al año
A10: Brazo | B10: A | C10: un solo brazo
A11: Pacientes en este brazo | B11: 1 | C11: pacientes de este brazo
A12: ¿Solo P. aeruginosa o mixto? | B12: solo Pseudomonas
A13: Clase de resistencia | B13: XDR | C13: según el antibiograma
A14: ¿De dónde sale esa clase? | B14: verificado de forma independiente | C14: lo verifiqué yo con Magiorakos; no me fié de la etiqueta del autor
A15: ¿Cumple criterio DTR? | B15: no derivable | C15: el artículo no da lo necesario
A16: Vía de administración | B16: topica/local
A17: ¿Fago solo o con antibiótico? | B17: fago + antibiotico
A18: Éxito clínico (nº pacientes) | B18: 1 | C18: de 1 paciente
A19: ¿Cómo define el AUTOR el éxito clínico? | B19: Infección erradicada; sin dolor, PCR normal, sin aflojamiento a 10 meses | C19: la definición DEL AUTOR, copiada, no la mía
A20: Eventos adversos (nº) | B20: 0 | C20: cero notificados; NO es lo mismo que NA
A21: Erradicación microbiológica (nº) | B21: 1
A22: Fallecidos (nº) | B22: 0
A23: Estancia hospitalaria (días) | B23: NA | C23: el artículo no lo dice
A24: Aparición de resistencia al fago (nº) | B24: NA | C24: el artículo no lo dice
A25: Diseño del estudio | B25: caso clinico
A26: Año de publicación | B26: 2020
A27: Nivel de la revista | B27: medio (Antimicrob Agents Chemother)
A28: País del estudio | B28: Alemania (Berlín)
A29: ¿Dónde viste estos datos? | B29: pp.1-2 Case Presentation; Tabla 1 antibiograma | C29: dónde lo vi; obligatorio para cualquier cifra
A30: Estado de esta extracción | B30: COMPLETA
A31: Si algo quedó incompleto, ¿por qué? | B31: NA
A33: EJEMPLO 2 — varios brazos
A34: Pirnay 2024, cohorte de 100 casos. Aquí está el error más común:
A35: los brazos NO son grupos de tratamiento, son clases de resistencia.
A36: Todos los pacientes recibieron lo mismo, fago más antibiótico. Lo que separa
A37: las filas es que el artículo permite contar desenlaces aparte en XDR, MDR y PDR.
A38: Se copia la fila tres veces, con el MISMO Nº y el Brazo en A, B y C.
A40: Brazo | B40: Clase de resistencia | C40: Pacientes | D40: Éxito clínico | E40: Eventos adversos | F40: Fallecidos
A41: A | B41: XDR | C41: 7 | D41: 6 | E41: 2 | F41: 2
A42: B | B42: MDR | C42: 23 | D42: 16 | E42: 4 | F42: 2
A43: C | B43: PDR | C43: 2 | D43: 1 | E43: 0 | F43: 0
A45: El resto de columnas (vía, modalidad, revista, país…) se repite igual en las tres.
...
